Exception on / [POST]
Traceback (most recent call last):
  File "C:\Users\miloslav\AppData\Local\Programs\Python\Python37-32\lib\site-packages\flask\app.py", line 1982, in wsgi_app
    response = self.full_dispatch_request()
  File "C:\Users\miloslav\AppData\Local\Programs\Python\Python37-32\lib\site-packages\flask\app.py", line 1614, in full_dispatch_request
    rv = self.handle_user_exception(e)
  File "C:\Users\miloslav\AppData\Local\Programs\Python\Python37-32\lib\site-packages\flask\app.py", line 1517, in handle_user_exception
    reraise(exc_type, exc_value, tb)
  File "C:\Users\miloslav\AppData\Local\Programs\Python\Python37-32\lib\site-packages\flask\_compat.py", line 33, in reraise
    raise value
  File "C:\Users\miloslav\AppData\Local\Programs\Python\Python37-32\lib\site-packages\flask\app.py", line 1612, in full_dispatch_request
    rv = self.dispatch_request()
  File "C:\Users\miloslav\AppData\Local\Programs\Python\Python37-32\lib\site-packages\flask\app.py", line 1598, in dispatch_request
    return self.view_functions[rule.endpoint](**req.view_args)
  File "C:/Users/miloslav/PycharmProjects/CYOA/app.py", line 73, in main
    js = Get_Event_by_ID(conn, event_id, session_id, user_id, "1.0",message_id,description2)
  File "C:\Users\miloslav\PycharmProjects\CYOA\API.py", line 61, in Get_Event_by_ID
    if rows[0][5] != "":
IndexError: list index out of range
